<?xml version="1.0" encoding="UTF-8"?>
<testng-results ignored="0" total="2" passed="0" failed="2" skipped="0">
  <reporter-output>
  </reporter-output>
  <suite started-at="2024-10-07T23:20:49 BDT" name="Suite" finished-at="2024-10-07T23:21:02 BDT" duration-ms="12170">
    <groups>
    </groups>
    <test started-at="2024-10-07T23:20:49 BDT" name="Test" finished-at="2024-10-07T23:21:02 BDT" duration-ms="12170">
      <class name="com.convay.testcases.FailedLoginToTestExtentReport">
        <test-method is-config="true" signature="setUpSuite()[pri:0, instance:com.convay.testcases.FailedLoginToTestExtentReport@5fe94a96]" started-at="2024-10-07T23:20:49 BDT" name="setUpSuite" finished-at="2024-10-07T23:20:49 BDT" duration-ms="6" status="PASS">
          <reporter-output>
          </reporter-output>
        </test-method> <!-- setUpSuite -->
        <test-method is-config="true" signature="setUp()[pri:0, instance:com.convay.testcases.FailedLoginToTestExtentReport@5fe94a96]" started-at="2024-10-07T23:20:50 BDT" name="setUp" finished-at="2024-10-07T23:21:01 BDT" duration-ms="11363" status="PASS">
          <reporter-output>
          </reporter-output>
        </test-method> <!-- setUp -->
        <test-method signature="LoginFailed(java.lang.String,java.lang.String)[pri:1, instance:com.convay.testcases.FailedLoginToTestExtentReport@5fe94a96]" started-at="2024-10-07T23:21:01 BDT" name="LoginFailed" data-provider="LoginDataProvider" finished-at="2024-10-07T23:21:01 BDT" duration-ms="149" status="FAIL">
          <params>
            <param index="0">
              <value>
                <![CDATA[Demo]]>
              </value>
            </param>
            <param index="1">
              <value>
                <![CDATA[TEst1234]]>
              </value>
            </param>
          </params>
          <exception class="java.lang.AssertionError">
            <message>
              <![CDATA[expected [true] but found [false]]]>
            </message>
            <full-stacktrace>
              <![CDATA[java.lang.AssertionError: expected [true] but found [false]
at org.testng.Assert.fail(Assert.java:110)
at org.testng.Assert.failNotEquals(Assert.java:1413)
at org.testng.Assert.assertTrue(Assert.java:56)
at org.testng.Assert.assertTrue(Assert.java:66)
at com.convay.testcases.FailedLoginToTestExtentReport.LoginFailed(FailedLoginToTestExtentReport.java:30)
at java.base/jdk.internal.reflect.DirectMethodHandleAccessor.invoke(DirectMethodHandleAccessor.java:104)
at java.base/java.lang.reflect.Method.invoke(Method.java:577)
at org.testng.internal.invokers.MethodInvocationHelper.invokeMethod(MethodInvocationHelper.java:139)
at org.testng.internal.invokers.TestInvoker.invokeMethod(TestInvoker.java:677)
at org.testng.internal.invokers.TestInvoker.invokeTestMethod(TestInvoker.java:221)
at org.testng.internal.invokers.MethodRunner.runInSequence(MethodRunner.java:50)
at org.testng.internal.invokers.TestInvoker$MethodInvocationAgent.invoke(TestInvoker.java:969)
at org.testng.internal.invokers.TestInvoker.invokeTestMethods(TestInvoker.java:194)
at org.testng.internal.invokers.TestMethodWorker.invokeTestMethods(TestMethodWorker.java:148)
at org.testng.internal.invokers.TestMethodWorker.run(TestMethodWorker.java:128)
at java.base/java.util.ArrayList.forEach(ArrayList.java:1511)
at org.testng.TestRunner.privateRun(TestRunner.java:829)
at org.testng.TestRunner.run(TestRunner.java:602)
at org.testng.SuiteRunner.runTest(SuiteRunner.java:437)
at org.testng.SuiteRunner.runSequentially(SuiteRunner.java:431)
at org.testng.SuiteRunner.privateRun(SuiteRunner.java:391)
at org.testng.SuiteRunner.run(SuiteRunner.java:330)
at org.testng.SuiteRunnerWorker.runSuite(SuiteRunnerWorker.java:52)
at org.testng.SuiteRunnerWorker.run(SuiteRunnerWorker.java:95)
at org.testng.TestNG.runSuitesSequentially(TestNG.java:1256)
at org.testng.TestNG.runSuitesLocally(TestNG.java:1176)
at org.testng.TestNG.runSuites(TestNG.java:1099)
at org.testng.TestNG.run(TestNG.java:1067)
at org.testng.remote.AbstractRemoteTestNG.run(AbstractRemoteTestNG.java:115)
at org.testng.remote.RemoteTestNG.initAndRun(RemoteTestNG.java:251)
at org.testng.remote.RemoteTestNG.main(RemoteTestNG.java:77)
]]>
            </full-stacktrace>
          </exception> <!-- java.lang.AssertionError -->
          <reporter-output>
          </reporter-output>
        </test-method> <!-- LoginFailed -->
        <test-method signature="LoginFailed(java.lang.String,java.lang.String)[pri:1, instance:com.convay.testcases.FailedLoginToTestExtentReport@5fe94a96]" started-at="2024-10-07T23:21:01 BDT" name="LoginFailed" data-provider="LoginDataProvider" finished-at="2024-10-07T23:21:02 BDT" duration-ms="76" status="FAIL">
          <params>
            <param index="0">
              <value>
                <![CDATA[]]>
              </value>
            </param>
            <param index="1">
              <value>
                <![CDATA[]]>
              </value>
            </param>
          </params>
          <exception class="java.lang.AssertionError">
            <message>
              <![CDATA[expected [true] but found [false]]]>
            </message>
            <full-stacktrace>
              <![CDATA[java.lang.AssertionError: expected [true] but found [false]
at org.testng.Assert.fail(Assert.java:110)
at org.testng.Assert.failNotEquals(Assert.java:1413)
at org.testng.Assert.assertTrue(Assert.java:56)
at org.testng.Assert.assertTrue(Assert.java:66)
at com.convay.testcases.FailedLoginToTestExtentReport.LoginFailed(FailedLoginToTestExtentReport.java:30)
at java.base/jdk.internal.reflect.DirectMethodHandleAccessor.invoke(DirectMethodHandleAccessor.java:104)
at java.base/java.lang.reflect.Method.invoke(Method.java:577)
at org.testng.internal.invokers.MethodInvocationHelper.invokeMethod(MethodInvocationHelper.java:139)
at org.testng.internal.invokers.TestInvoker.invokeMethod(TestInvoker.java:677)
at org.testng.internal.invokers.TestInvoker.invokeTestMethod(TestInvoker.java:221)
at org.testng.internal.invokers.MethodRunner.runInSequence(MethodRunner.java:50)
at org.testng.internal.invokers.TestInvoker$MethodInvocationAgent.invoke(TestInvoker.java:969)
at org.testng.internal.invokers.TestInvoker.invokeTestMethods(TestInvoker.java:194)
at org.testng.internal.invokers.TestMethodWorker.invokeTestMethods(TestMethodWorker.java:148)
at org.testng.internal.invokers.TestMethodWorker.run(TestMethodWorker.java:128)
at java.base/java.util.ArrayList.forEach(ArrayList.java:1511)
at org.testng.TestRunner.privateRun(TestRunner.java:829)
at org.testng.TestRunner.run(TestRunner.java:602)
at org.testng.SuiteRunner.runTest(SuiteRunner.java:437)
at org.testng.SuiteRunner.runSequentially(SuiteRunner.java:431)
at org.testng.SuiteRunner.privateRun(SuiteRunner.java:391)
at org.testng.SuiteRunner.run(SuiteRunner.java:330)
at org.testng.SuiteRunnerWorker.runSuite(SuiteRunnerWorker.java:52)
at org.testng.SuiteRunnerWorker.run(SuiteRunnerWorker.java:95)
at org.testng.TestNG.runSuitesSequentially(TestNG.java:1256)
at org.testng.TestNG.runSuitesLocally(TestNG.java:1176)
at org.testng.TestNG.runSuites(TestNG.java:1099)
at org.testng.TestNG.run(TestNG.java:1067)
at org.testng.remote.AbstractRemoteTestNG.run(AbstractRemoteTestNG.java:115)
at org.testng.remote.RemoteTestNG.initAndRun(RemoteTestNG.java:251)
at org.testng.remote.RemoteTestNG.main(RemoteTestNG.java:77)
]]>
            </full-stacktrace>
          </exception> <!-- java.lang.AssertionError -->
          <reporter-output>
          </reporter-output>
        </test-method> <!-- LoginFailed -->
        <test-method is-config="true" signature="tearDown()[pri:0, instance:com.convay.testcases.FailedLoginToTestExtentReport@5fe94a96]" started-at="2024-10-07T23:21:02 BDT" name="tearDown" finished-at="2024-10-07T23:21:02 BDT" duration-ms="113" status="PASS">
          <reporter-output>
          </reporter-output>
        </test-method> <!-- tearDown -->
      </class> <!-- com.convay.testcases.FailedLoginToTestExtentReport -->
    </test> <!-- Test -->
  </suite> <!-- Suite -->
</testng-results>
